Workbook

Sheet Tóm tắt
A1: Danh sách tính năng rút gọn: triển khai cho một tỉnh
A2: Bản rút gọn từ danh sách 105 chức năng. Triển khai trên cloud trong nước (VNG/GreenNode, FPT, Viettel).
A4: Số lượng tính năng theo đối tượng
A5: Đối tượng | B5: Tổng | C5: Giữ nguyên | D5: Rút gọn | E5: Đợt 1 | F5: Đợt 2 | G5: Kiểm tra
A6: 1. Chủ thể OCOP | B6: =COUNTIFS('Tính năng rút gọn'!$B$2:$B$300,$A6) -> 11 | C6: =COUNTIFS('Tính năng rút gọn'!$B$2:$B$300,$A6,'Tính năng rút gọn'!$E$2:$E$300,C$5) -> 9 | D6: =COUNTIFS('Tính năng rút gọn'!$B$2:$B$300,$A6,'Tính năng rút gọn'!$E$2:$E$300,D$5) -> 2 | E6: =COUNTIFS('Tính năng rút gọn'!$B$2:$B$300,$A6,'Tính năng rút gọn'!$F$2:$F$300,E$5) -> 10 | F6: =COUNTIFS('Tính năng rút gọn'!$B$2:$B$300,$A6,'Tính năng rút gọn'!$F$2:$F$300,F$5) -> 1
A7: 2. UBND xã/phường | B7: =COUNTIFS('Tính năng rút gọn'!$B$2:$B$300,$A7) -> 7 | C7: =COUNTIFS('Tính năng rút gọn'!$B$2:$B$300,$A7,'Tính năng rút gọn'!$E$2:$E$300,C$5) -> 7 | D7: =COUNTIFS('Tính năng rút gọn'!$B$2:$B$300,$A7,'Tính năng rút gọn'!$E$2:$E$300,D$5) -> 0 | E7: =COUNTIFS('Tính năng rút gọn'!$B$2:$B$300,$A7,'Tính năng rút gọn'!$F$2:$F$300,E$5) -> 7 | F7: =COUNTIFS('Tính năng rút gọn'!$B$2:$B$300,$A7,'Tính năng rút gọn'!$F$2:$F$300,F$5) -> 0
A8: 3. Sở NN&MT | B8: =COUNTIFS('Tính năng rút gọn'!$B$2:$B$300,$A8) -> 4 | C8: =COUNTIFS('Tính năng rút gọn'!$B$2:$B$300,$A8,'Tính năng rút gọn'!$E$2:$E$300,C$5) -> 2 | D8: =COUNTIFS('Tính năng rút gọn'!$B$2:$B$300,$A8,'Tính năng rút gọn'!$E$2:$E$300,D$5) -> 2 | E8: =COUNTIFS('Tính năng rút gọn'!$B$2:$B$300,$A8,'Tính năng rút gọn'!$F$2:$F$300,E$5) -> 3 | F8: =COUNTIFS('Tính năng rút gọn'!$B$2:$B$300,$A8,'Tính năng rút gọn'!$F$2:$F$300,F$5) -> 1
A9: 4. Hội đồng đánh giá cấp tỉnh | B9: =COUNTIFS('Tính năng rút gọn'!$B$2:$B$300,$A9) -> 11 | C9: =COUNTIFS('Tính năng rút gọn'!$B$2:$B$300,$A9,'Tính năng rút gọn'!$E$2:$E$300,C$5) -> 9 | D9: =COUNTIFS('Tính năng rút gọn'!$B$2:$B$300,$A9,'Tính năng rút gọn'!$E$2:$E$300,D$5) -> 2 | E9: =COUNTIFS('Tính năng rút gọn'!$B$2:$B$300,$A9,'Tính năng rút gọn'!$F$2:$F$300,E$5) -> 10 | F9: =COUNTIFS('Tính năng rút gọn'!$B$2:$B$300,$A9,'Tính năng rút gọn'!$F$2:$F$300,F$5) -> 1
A10: 5. Tổ tư vấn | B10: =COUNTIFS('Tính năng rút gọn'!$B$2:$B$300,$A10) -> 8 | C10: =COUNTIFS('Tính năng rút gọn'!$B$2:$B$300,$A10,'Tính năng rút gọn'!$E$2:$E$300,C$5) -> 8 | D10: =COUNTIFS('Tính năng rút gọn'!$B$2:$B$300,$A10,'Tính năng rút gọn'!$E$2:$E$300,D$5) -> 0 | E10: =COUNTIFS('Tính năng rút gọn'!$B$2:$B$300,$A10,'Tính năng rút gọn'!$F$2:$F$300,E$5) -> 8 | F10: =COUNTIFS('Tính năng rút gọn'!$B$2:$B$300,$A10,'Tính năng rút gọn'!$F$2:$F$300,F$5) -> 0
A11: 6. Thành viên hội đồng | B11: =COUNTIFS('Tính năng rút gọn'!$B$2:$B$300,$A11) -> 8 | C11: =COUNTIFS('Tính năng rút gọn'!$B$2:$B$300,$A11,'Tính năng rút gọn'!$E$2:$E$300,C$5) -> 8 | D11: =COUNTIFS('Tính năng rút gọn'!$B$2:$B$300,$A11,'Tính năng rút gọn'!$E$2:$E$300,D$5) -> 0 | E11: =COUNTIFS('Tính năng rút gọn'!$B$2:$B$300,$A11,'Tính năng rút gọn'!$F$2:$F$300,E$5) -> 8 | F11: =COUNTIFS('Tính năng rút gọn'!$B$2:$B$300,$A11,'Tính năng rút gọn'!$F$2:$F$300,F$5) -> 0
A12: 7. Quản trị hệ thống | B12: =COUNTIFS('Tính năng rút gọn'!$B$2:$B$300,$A12) -> 9 | C12: =COUNTIFS('Tính năng rút gọn'!$B$2:$B$300,$A12,'Tính năng rút gọn'!$E$2:$E$300,C$5) -> 7 | D12: =COUNTIFS('Tính năng rút gọn'!$B$2:$B$300,$A12,'Tính năng rút gọn'!$E$2:$E$300,D$5) -> 2 | E12: =COUNTIFS('Tính năng rút gọn'!$B$2:$B$300,$A12,'Tính năng rút gọn'!$F$2:$F$300,E$5) -> 9 | F12: =COUNTIFS('Tính năng rút gọn'!$B$2:$B$300,$A12,'Tính năng rút gọn'!$F$2:$F$300,F$5) -> 0
A13: 8. Cổng công khai (xác thực QR) | B13: =COUNTIFS('Tính năng rút gọn'!$B$2:$B$300,$A13) -> 1 | C13: =COUNTIFS('Tính năng rút gọn'!$B$2:$B$300,$A13,'Tính năng rút gọn'!$E$2:$E$300,C$5) -> 0 | D13: =COUNTIFS('Tính năng rút gọn'!$B$2:$B$300,$A13,'Tính năng rút gọn'!$E$2:$E$300,D$5) -> 1 | E13: =COUNTIFS('Tính năng rút gọn'!$B$2:$B$300,$A13,'Tính năng rút gọn'!$F$2:$F$300,E$5) -> 0 | F13: =COUNTIFS('Tính năng rút gọn'!$B$2:$B$300,$A13,'Tính năng rút gọn'!$F$2:$F$300,F$5) -> 1
A14: 9. Dùng chung | B14: =COUNTIFS('Tính năng rút gọn'!$B$2:$B$300,$A14) -> 6 | C14: =COUNTIFS('Tính năng rút gọn'!$B$2:$B$300,$A14,'Tính năng rút gọn'!$E$2:$E$300,C$5) -> 5 | D14: =COUNTIFS('Tính năng rút gọn'!$B$2:$B$300,$A14,'Tính năng rút gọn'!$E$2:$E$300,D$5) -> 1 | E14: =COUNTIFS('Tính năng rút gọn'!$B$2:$B$300,$A14,'Tính năng rút gọn'!$F$2:$F$300,E$5) -> 6 | F14: =COUNTIFS('Tính năng rút gọn'!$B$2:$B$300,$A14,'Tính năng rút gọn'!$F$2:$F$300,F$5) -> 0
A15: Tổng cộng | B15: =SUM(B6:B14) -> 65 | C15: =SUM(C6:C14) -> 55 | D15: =SUM(D6:D14) -> 10 | E15: =SUM(E6:E14) -> 61 | F15: =SUM(F6:F14) -> 4 | G15: =IF(AND(B15=C15+D15,B15=E15+F15,B15=COUNTA('Tính năng rút gọn'!$A$2:$A$300)),"OK","Lỗi") -> OK
A17: Tính năng hoãn, làm ngoài hệ thống, gộp hoặc ngoài phạm vi
A18: Hoãn | B18: =COUNTIF('Hoãn hoặc cắt'!$D$2:$D$300,$A18) -> 16
A19: Làm ngoài hệ thống | B19: =COUNTIF('Hoãn hoặc cắt'!$D$2:$D$300,$A19) -> 10
A20: Gộp vào chức năng khác | B20: =COUNTIF('Hoãn hoặc cắt'!$D$2:$D$300,$A20) -> 5
A21: Ngoài phạm vi (Bộ không dùng hệ thống) | B21: =COUNTIF('Hoãn hoặc cắt'!$D$2:$D$300,$A21) -> 10
A22: Tổng số mã bị hoãn hoặc cắt | B22: =SUM(B18:B21) -> 41
A23: Mã gốc được giữ (không tính DC-09 một phần) | B23: =B15-1 -> 64
A24: Tổng mã gốc (kiểm tra bằng 105) | B24: =B22+B23 -> 105 | C24: =IF(B24=105,"OK","Lỗi") -> OK
A26: Chú giải
A27: Giữ nguyên | B27: Giữ đúng như danh sách 105 chức năng
A28: Rút gọn | B28: Giữ nhưng bớt phạm vi, xem cột Ghi chú
A29: Đợt 1 | B29: Luồng lõi, làm trước
A30: Đợt 2 | B30: QR và thống kê, có thể làm sau lõi (đề xuất)
A32: Cột Trạng thái ở sheet Tính năng rút gọn dùng menu thả xuống để theo dõi tiến độ; thêm dòng mới trong vùng A2:I300 thì bảng đếm tự cập nhật.

Sheet Tính năng rút gọn
A1: Mã gốc | B1: Đối tượng | C1: Nhóm chức năng | D1: Tính năng (bản rút gọn) | E1: Mức giữ | F1: Đợt triển khai | G1: Luồng xử lý | H1: Ghi chú | I1: Trạng thái
A2: CT-01 | B2: 1. Chủ thể OCOP | C2: Tài khoản & hồ sơ | D2: Đăng ký tài khoản, đăng nhập an toàn | E2: Giữ nguyên | F2: Đợt 1 | G2: L01 | I2: Chưa làm
A3: CT-02 | B3: 1. Chủ thể OCOP | C3: Tài khoản & hồ sơ | D3: Quản lý hồ sơ pháp lý (GPKD, VSATTP, công bố chất lượng...) | E3: Giữ nguyên | F3: Đợt 1 | G3: L01 | I3: Chưa làm
A4: CT-03 | B4: 1. Chủ thể OCOP | C4: Tài khoản & hồ sơ | D4: Tạo/sửa hồ sơ sản phẩm theo 6 nhóm OCOP, lưu nháp rồi gửi | E4: Giữ nguyên | F4: Đợt 1 | G4: L02 | I4: Chưa làm
A5: CT-05 | B5: 1. Chủ thể OCOP | C5: Minh chứng & tự đánh giá | D5: Upload minh chứng gắn theo từng tiêu chí trong bộ 100 điểm | E5: Giữ nguyên | F5: Đợt 1 | G5: L02 | I5: Chưa làm
A6: CT-06 | B6: 1. Chủ thể OCOP | C6: Minh chứng & tự đánh giá | D6: Tự chấm điểm thử, ước lượng số sao | E6: Giữ nguyên | F6: Đợt 1 | G6: L02 | I6: Chưa làm
A7: CT-09 | B7: 1. Chủ thể OCOP | C7: Nộp hồ sơ & theo dõi | D7: Nộp hồ sơ về UBND xã | E7: Giữ nguyên | F7: Đợt 1 | G7: L03 | I7: Chưa làm
A8: CT-10 | B8: 1. Chủ thể OCOP | C8: Nộp hồ sơ & theo dõi | D8: Theo dõi trạng thái hồ sơ (đã tiếp nhận / yêu cầu bổ sung / đã chuyển tỉnh...) | E8: Giữ nguyên | F8: Đợt 1 | G8: L03 | I8: Chưa làm
A9: CT-11 | B9: 1. Chủ thể OCOP | C9: Nộp hồ sơ & theo dõi | D9: Xem yêu cầu bổ sung và nộp lại hồ sơ | E9: Giữ nguyên | F9: Đợt 1 | G9: L04 | I9: Chưa làm
A10: CT-12 | B10: 1. Chủ thể OCOP | C10: Nộp hồ sơ & theo dõi | D10: Nhắc hạn nộp các đợt qua email và trong ứng dụng | E10: Rút gọn | F10: Đợt 1 | G10: L03 | H10: Không có SMS, Zalo | I10: Chưa làm
A11: CT-13 | B11: 1. Chủ thể OCOP | C11: Nộp hồ sơ & theo dõi | D11: Nhận thông báo kết quả, xem nhận xét của hội đồng | E11: Giữ nguyên | F11: Đợt 1 | G11: L16 | I11: Chưa làm
A12: CT-15 | B12: 1. Chủ thể OCOP | C12: Sau công nhận | D12: Tải giấy chứng nhận PDF có mã QR | E12: Rút gọn | F12: Đợt 2 | G12: L16 | H12: Không có màn hình quản lý QR riêng | I12: Chưa làm
A13: XA-01 | B13: 2. UBND xã/phường | C13: Tiếp nhận | D13: Danh sách hồ sơ của chủ thể trên địa bàn, ghi nhận ngày nhận | E13: Giữ nguyên | F13: Đợt 1 | G13: L05 | I13: Chưa làm
A14: XA-02 | B14: 2. UBND xã/phường | C14: Tiếp nhận | D14: Kiểm tra tính đầy đủ tài liệu và tính hợp lệ của chủ thể | E14: Giữ nguyên | F14: Đợt 1 | G14: L05 | I14: Chưa làm
A15: XA-03 | B15: 2. UBND xã/phường | C15: Tiếp nhận | D15: Phân công cán bộ xử lý hồ sơ | E15: Giữ nguyên | F15: Đợt 1 | G15: L05 | I15: Chưa làm
A16: XA-04 | B16: 2. UBND xã/phường | C16: Đánh giá sơ bộ | D16: Checklist sơ bộ: nguồn gốc nguyên liệu, lao động địa phương, bản sắc văn hóa - trí tuệ bản địa | E16: Giữ nguyên | F16: Đợt 1 | G16: L06 | I16: Chưa làm
A17: XA-05 | B17: 2. UBND xã/phường | C17: Đánh giá sơ bộ | D17: Yêu cầu chủ thể bổ sung hồ sơ | E17: Giữ nguyên | F17: Đợt 1 | G17: L04 | I17: Chưa làm
A18: XA-07 | B18: 2. UBND xã/phường | C18: Gửi lên tỉnh | D18: Lập biên bản, văn bản đề xuất gửi tỉnh, đính kèm toàn bộ tài liệu | E18: Giữ nguyên | F18: Đợt 1 | G18: L06 | I18: Chưa làm
A19: XA-08 | B19: 2. UBND xã/phường | C19: Gửi lên tỉnh | D19: Chọn đợt gửi và theo dõi sau khi gửi | E19: Giữ nguyên | F19: Đợt 1 | G19: L06 | I19: Chưa làm
A20: SO-01 | B20: 3. Sở NN&MT | C20: Quản lý đợt | D20: Mở/đóng đợt đánh giá, thiết lập hạn nộp | E20: Giữ nguyên | F20: Đợt 1 | G20: L07 | I20: Chưa làm
A21: SO-02 | B21: 3. Sở NN&MT | C21: Quản lý hồ sơ | D21: Danh sách hồ sơ từ các xã trong toàn tỉnh, lọc theo đợt/trạng thái | E21: Giữ nguyên | F21: Đợt 1 | G21: L08 | I21: Chưa làm
A22: SO-04 | B22: 3. Sở NN&MT | C22: Chuyển Bộ | D22: Công cụ xuất gói hồ sơ 5 sao (từ 90 điểm) để gửi đánh giá ngoài hệ thống; đánh dấu trạng thái sau khi gửi | E22: Rút gọn | F22: Đợt 1 | G22: L17 | H22: Bộ NN&MT không dùng hệ thống: gửi và nhận kết quả bằng văn bản. Gói gồm hồ sơ, báo cáo của Tổ tư vấn và của Hội đồng, quyết định của Chủ tịch UBND tỉnh. Hệ thống không nhập kết quả của Bộ | I22: Chưa làm
A23: SO-06 | B23: 3. Sở NN&MT | C23: Báo cáo | D23: Bảng thống kê theo đợt, nhóm sản phẩm, đơn vị; xuất Excel | E23: Rút gọn | F23: Đợt 2 | G23: L22 | H23: Gộp SO-07; bộ lọc cơ bản | I23: Chưa làm
A24: HD-01 | B24: 4. Hội đồng đánh giá cấp tỉnh | C24: Thành lập hội đồng | D24: Thành lập hội đồng, quản lý thành viên, chủ tịch/thư ký hội đồng | E24: Giữ nguyên | F24: Đợt 1 | G24: L09 | I24: Chưa làm
A25: HD-02 | B25: 4. Hội đồng đánh giá cấp tỉnh | C25: Thành lập hội đồng | D25: Phân công hồ sơ cho thành viên/chuyên gia | E25: Giữ nguyên | F25: Đợt 1 | G25: L09 | I25: Chưa làm
A26: HD-03 | B26: 4. Hội đồng đánh giá cấp tỉnh | C26: Thành lập hội đồng | D26: Phân công Tổ tư vấn phụ trách từng hồ sơ / từng đợt | E26: Giữ nguyên | F26: Đợt 1 | G26: L09 | I26: Chưa làm
A27: HD-04 | B27: 4. Hội đồng đánh giá cấp tỉnh | C27: Chấm điểm | D27: Chấm điểm trực tuyến theo bộ tiêu chí, tự cộng điểm, tính điểm trung bình | E27: Giữ nguyên | F27: Đợt 1 | G27: L15 | I27: Chưa làm
A28: HD-05 | B28: 4. Hội đồng đánh giá cấp tỉnh | C28: Chấm điểm | D28: Gợi ý phân hạng tự động theo điểm | E28: Giữ nguyên | F28: Đợt 1 | G28: L15 | I28: Chưa làm
A29: HD-06 | B29: 4. Hội đồng đánh giá cấp tỉnh | C29: Chấm điểm | D29: Chọn chế độ chấm cho đợt: trực tiếp hoặc dựa trên Tổ tư vấn | E29: Rút gọn | F29: Đợt 1 | G29: L09 | H29: Bỏ chế độ kết hợp | I29: Chưa làm
A30: HD-08 | B30: 4. Hội đồng đánh giá cấp tỉnh | C30: Chấm điểm | D30: Khóa điểm bất biến sau khi chốt | E30: Giữ nguyên | F30: Đợt 1 | G30: L15 | I30: Chưa làm
A31: HD-09 | B31: 4. Hội đồng đánh giá cấp tỉnh | C31: Họp & quyết định | D31: Họp hội đồng: bảng tổng hợp điểm, biên bản, quyết định công nhận (sinh từ mẫu Word) | E31: Rút gọn | F31: Đợt 1 | G31: L15 | H31: Gộp TM-11 (tài liệu họp) | I31: Chưa làm
A32: HD-10 | B32: 4. Hội đồng đánh giá cấp tỉnh | C32: Họp & quyết định | D32: Gửi kết quả cho sản phẩm không đạt kèm nhận xét | E32: Giữ nguyên | F32: Đợt 1 | G32: L16 | I32: Chưa làm
A33: HD-11 | B33: 4. Hội đồng đánh giá cấp tỉnh | C33: Giấy chứng nhận | D33: Cấp giấy chứng nhận 3-4 sao, xuất PDF, số hiệu, ngày cấp | E33: Giữ nguyên | F33: Đợt 1 | G33: L16 | I33: Chưa làm
A34: HD-12 | B34: 4. Hội đồng đánh giá cấp tỉnh | C34: Giấy chứng nhận | D34: Gắn mã QR vào giấy chứng nhận | E34: Giữ nguyên | F34: Đợt 2 | G34: L16 | H34: Làm sau lõi | I34: Chưa làm
A35: TM-01 | B35: 5. Tổ tư vấn | C35: Thẩm định hồ sơ | D35: Danh sách hồ sơ được giao thẩm định theo đợt, theo hạn xử lý | E35: Giữ nguyên | F35: Đợt 1 | G35: L10 | I35: Chưa làm
A36: TM-02 | B36: 5. Tổ tư vấn | C36: Thẩm định hồ sơ | D36: Rà soát hồ sơ và minh chứng theo từng tiêu chí, đánh dấu thiếu hoặc không hợp lệ | E36: Giữ nguyên | F36: Đợt 1 | G36: L10 | I36: Chưa làm
A37: TM-05 | B37: 5. Tổ tư vấn | C37: Điểm đề xuất | D37: Chấm điểm đề xuất từng tiêu chí kèm căn cứ và minh chứng viện dẫn | E37: Giữ nguyên | F37: Đợt 1 | G37: L10 | I37: Chưa làm
A38: TM-06 | B38: 5. Tổ tư vấn | C38: Điểm đề xuất | D38: Soạn nhận xét, báo cáo thẩm định, các điểm cần hội đồng lưu ý | E38: Giữ nguyên | F38: Đợt 1 | G38: L10 | I38: Chưa làm
A39: TM-07 | B39: 5. Tổ tư vấn | C39: Điểm đề xuất | D39: Chốt và phát hành báo cáo Tổ tư vấn (khóa phiên bản) trước khi chia sẻ cho thành viên | E39: Giữ nguyên | F39: Đợt 1 | G39: L11 | I39: Chưa làm
A40: TM-08 | B40: 5. Tổ tư vấn | C40: Sao chép dữ liệu cho thành viên | D40: Sao chép dữ liệu của Tổ tư vấn (điểm đề xuất, nhận xét, căn cứ) vào phiếu chấm của thành viên hội đồng, chọn toàn bộ hoặc theo từng tiêu chí | E40: Giữ nguyên | F40: Đợt 1 | G40: L12 | I40: Chưa làm
...

Sheet Hoãn hoặc cắt
A1: Mã gốc | B1: Đối tượng gốc | C1: Tính năng gốc | D1: Hướng xử lý | E1: Thay thế / ghi chú
A2: CT-04 | B2: 1. Chủ thể OCOP (DN, HTX, hộ sản xuất) | C2: Tạo câu chuyện sản phẩm (bản sắc, nguồn gốc, truyền thống) | D2: Hoãn | E2: Chủ thể mô tả bản sắc, nguồn gốc ngay trong trường văn bản của hồ sơ sản phẩm
A3: CT-07 | B3: 1. Chủ thể OCOP (DN, HTX, hộ sản xuất) | C3: Hướng dẫn chi tiết từng tiêu chí và gợi ý nâng điểm | D3: Hoãn | E3: Hiển thị mô tả từng tiêu chí ngay trong form; chưa có gợi ý nâng điểm tự động
A4: CT-08 | B4: 1. Chủ thể OCOP (DN, HTX, hộ sản xuất) | C4: Cảnh báo minh chứng sắp hết hạn (GPKD, giấy VSATTP, kết quả kiểm nghiệm) | D4: Hoãn | E4: Vẫn lưu ngày hiệu lực của giấy tờ để bổ sung cảnh báo sau
A5: CT-14 | B5: 1. Chủ thể OCOP (DN, HTX, hộ sản xuất) | C5: Đăng ký đánh giá lại / nâng hạng (ví dụ 3 sao lên 4 sao) | D5: Hoãn | E5: Chủ thể tạo hồ sơ mới ở đợt kế tiếp
A6: CT-16 | B6: 1. Chủ thể OCOP (DN, HTX, hộ sản xuất) | C6: Khiếu nại / phản hồi kết quả đánh giá | D6: Làm ngoài hệ thống | E6: Khiếu nại bằng văn bản; kết luận ghi vào tệp đính kèm của hồ sơ
A7: CT-17 | B7: 1. Chủ thể OCOP (DN, HTX, hộ sản xuất) | C7: FAQ, video hướng dẫn, mẫu hồ sơ, ví dụ hồ sơ thành công | D7: Làm ngoài hệ thống | E7: Trang hướng dẫn tĩnh hoặc tài liệu PDF
A8: XA-06 | B8: 2. UBND xã/phường | C8: Kiểm tra thực địa trên mobile: ảnh có geotag, chạy được khi mạng yếu | D8: Làm ngoài hệ thống | E8: Biên bản thực địa và ảnh đính kèm như tệp thường
A9: XA-09 | B9: 2. UBND xã/phường | C9: Thống kê số hồ sơ đã xử lý, đạt/không đạt sơ bộ trong đợt | D9: Gộp vào chức năng khác | E9: Dùng bộ lọc danh sách và xuất Excel (DC-04, DC-05)
A10: SO-03 | B10: 3. Sở NN&MT (thường trực cấp tỉnh) | C10: Mã tracking riêng cho từng hồ sơ | D10: Gộp vào chức năng khác | E10: Mã hồ sơ do hệ thống sinh sẵn dùng làm mã theo dõi
A11: SO-05 | B11: 3. Sở NN&MT (thường trực cấp tỉnh) | C11: Thu hồi / gia hạn giấy chứng nhận khi không duy trì tiêu chuẩn | D11: Hoãn | E11: Chờ văn bản quy định điều kiện thu hồi; dữ liệu giấy chứng nhận có sẵn trường trạng thái
A12: SO-07 | B12: 3. Sở NN&MT (thường trực cấp tỉnh) | C12: Thống kê phân bố theo địa phương, nhóm sản phẩm | D12: Gộp vào chức năng khác | E12: Gộp vào bảng thống kê SO-06
... A42: DC-11 | B42: 10. Dùng chung / phi chức năng | C42: API tích hợp với hệ thống khác của chính quyền | D42: Hoãn | E42: Chưa có yêu cầu tích hợp

Sheet Triển khai cloud VN
A1: Thành phần | B1: Đề xuất cho bản rút gọn | C1: Ghi chú theo nhà cung cấp (VNG/GreenNode, FPT, Viettel)
A2: Máy chủ ứng dụng | B2: 1 VM (hoặc 2 VM sau này) chạy Docker Compose: Caddy hoặc Nginx, web Next.js, worker. Ước lượng 2-4 vCPU, 8 GB RAM | C2: Cả ba nhà cung cấp có máy chủ ảo. Không mở cổng trực tiếp ra internet ngoài 80/443
A3: Cân bằng tải và WAF | B3: Tùy chọn ở giai đoạn đầu; nên có khi mở cổng xác thực QR công khai | C3: Nguồn công khai cho thấy FPT Cloud có WAF và Load Balancing; GreenNode (VNG) có dịch vụ lọc lưu lượng HTTP/HTTPS. Cần xác nhận tên gói và giá
A4: PostgreSQL | B4: Ưu tiên dịch vụ quản lý có sao lưu tự động; nếu không có thì chạy Postgres trên VM riêng, sao lưu bằng pgBackRest hoặc pg_dump kèm lưu WAL ra object storage | C4: GreenNode vDB có PostgreSQL Cluster (2 đến 10 node, failover tự động, tích hợp vBackup), có ở vùng HAN-01 theo cập nhật 2026. FPT và Viettel: chưa kiểm chứng được dịch vụ PostgreSQL quản lý, cần hỏi nhà cung cấp
A5: Lưu trữ tệp | B5: Object storage S3-compatible qua interface FileStore (adapter S3), thay cho volume trên đĩa | C5: GreenNode vStorage hỗ trợ S3 API, pre-signed URL, CORS, versioning. FPT Object Storage tương thích S3. Viettel IDC công bố dịch vụ lưu trữ S3-compatible (thông tin 2022). Cần xác nhận chi tiết với từng nhà cung cấp
A6: Điểm cần kiểm thử với S3 của nhà cung cấp | B6: Endpoint kiểu path-style, pre-signed URL, multipart, CORS, versioning, checksum mặc định của AWS SDK v3 | C6: GreenNode: CopyObject trả 501 khi bucket hoặc object bật SSE-S3 hoặc SSE-C. Nếu SDK gửi checksum mà nhà cung cấp không hỗ trợ thì đặt cấu hình chỉ tính checksum khi bắt buộc
A7: Sao lưu và khôi phục | B7: Sao lưu DB hằng đêm cộng lưu WAL; bật versioning cho bucket; bản sao thứ hai ở vùng hoặc nhà cung cấp khác; diễn tập khôi phục định kỳ | C7: Object Lock (nếu nhà cung cấp hỗ trợ) giúp chống xóa nhầm hoặc mã độc
A8: Mạng | B8: Mạng riêng (VPC): DB và storage đi qua private endpoint khi có | C8: GreenNode có Private Endpoint tới vStorage và các dịch vụ khác
A9: Email | B9: SMTP của cơ quan hoặc dịch vụ trong nước; cấu hình SPF, DKIM, DMARC | C9: Quan trọng cho thông báo nhắc hạn và kết quả
A10: Giám sát | B10: Log JSON, giám sát uptime, cảnh báo dung lượng đĩa và DB; công cụ giám sát của nhà cung cấp nếu có | C10: GreenNode có vMonitor; các nhà cung cấp khác cần xác nhận
A11: Kubernetes | B11: Chưa cần ở bản rút gọn | C11: GreenNode có VKS nếu sau này cần
A12: Tuân thủ | B12: Xác nhận cấp độ an toàn thông tin của hệ thống và yêu cầu đối với nhà cung cấp; dữ liệu đặt tại trung tâm dữ liệu trong nước | C12: Cần xác nhận với đơn vị chủ quản và pháp chế

Sheet Lưu ý và giả định
A1: Loại | B1: Nội dung | C1: Chi tiết
A2: Phạm vi | B2: Bản rút gọn dành cho một tỉnh | C2: Gồm 64 mã chức năng gốc cộng phần xác thực hai lớp của DC-09; 41 mã còn lại hoãn, làm ngoài hệ thống, gộp hoặc ngoài phạm vi (sheet Hoãn hoặc cắt).
A3: Phạm vi | B3: Bộ NN&MT không phải người dùng hệ thống | C3: Hệ thống chỉ có công cụ xuất gói hồ sơ 5 sao (SO-04). Gửi đánh giá và nhận kết quả bằng văn bản ngoài hệ thống. Sở chỉ đánh dấu trạng thái: Đã gửi đề nghị 5 sao, rồi Chuyển về công nhận cấp tỉnh (khi Bộ trả về) hoặc Đóng hồ sơ (kết quả khác).
A4: Giả định | B4: Cột Đợt triển khai | C4: Đợt 1 là luồng lõi. Đợt 2 gồm 4 mục có thể làm sau lõi: CT-15, SO-06, HD-12, CK-02 (QR và thống kê). Đây là đề xuất, có thể điều chỉnh.
A5: Cần kiểm tra | B5: Phân bổ điểm Phần A/B/C = 40/25/35 và ngưỡng từng hạng | C5: Chưa đối chiếu với Phụ lục QĐ 26/2026/QĐ-TTg; hệ thống cấu hình qua bộ tiêu chí có phiên bản.
A6: Cần kiểm tra | B6: Mốc thời gian các đợt (xã, tỉnh) | C6: Lưu trong cấu hình đợt, không viết cứng.
A7: Cần kiểm tra | B7: Vai trò và thẩm quyền của Tổ tư vấn | C7: Xác nhận đơn vị đảm nhiệm và quy chế hội đồng (số thành viên chấm, trách nhiệm điểm xác nhận).
A8: Rủi ro | B8: Thành viên chấp nhận điểm của Tổ tư vấn mà không xem xét | C8: Sao chép một chiều, bắt buộc xác nhận từng phiếu, bắt buộc ghi lý do khi điểm khác với điểm của Tổ tư vấn, lưu điểm gốc của Tổ tư vấn.
A9: Cần kiểm tra | B9: Dịch vụ cloud trong nước | C9: Các thông tin về PostgreSQL quản lý, S3, WAF trên VNG (GreenNode), FPT, Viettel lấy từ nguồn công khai; cần xác nhận lại với nhà cung cấp trước khi chọn.
A10: Cần kiểm tra | B10: Báo cáo của Tổ tư vấn có bắt buộc trước khi Hội đồng họp không | C10: Một số tỉnh quy định Hội đồng chỉ họp khi có báo cáo thẩm tra của Tổ tư vấn (ví dụ quy chế của Ninh Bình). Nếu bắt buộc thì chế độ chấm trực tiếp cần xem lại.
A11: Pháp lý | B11: NĐ 13/2023 và cấp độ an toàn thông tin | C11: Xác nhận yêu cầu cụ thể với đơn vị chủ quản.
